Workbook

Sheet Testing
A1: employee_id | B1: employee_name | C1: department | D1: job_title | E1: start_date | F1: terminated_date | G1: status | H1: Finance (status) | I1: Last Log in | J1: Before or After | K1: Payroll (active?) | L1: Last Log in | M1: Before or After
A2: EMP0003 | B2: Henry Murphy | C2: Human Resources | D2: HR Business Partner | E2: 45208 | F2: 45967 | G2: Terminated | H2: =_xlfn.XLOOKUP(B2,Finance!C:C,Finance!E:E,,0) -> #N/A | I2: =_xlfn.XLOOKUP(B2,Finance!C:C,Finance!G:G,,0) -> #N/A | J2: N/A | K2: =_xlfn.XLOOKUP(B2,Payroll!D:D,Payroll!F:F,,0) -> yes | L2: =_xlfn.XLOOKUP(B2,Payroll!D:D,Payroll!H:H,,0) -> 45994 | M2: =IF(L2>F2,"After","Before") -> After
A3: EMP0006 | B3: Henry Bailey | C3: Customer Support | D3: Service Desk Analyst | E3: 44765 | F3: 45719 | G3: Terminated | H3: =_xlfn.XLOOKUP(B3,Finance!C:C,Finance!E:E,,0) -> #N/A | I3: =_xlfn.XLOOKUP(B3,Finance!C:C,Finance!G:G,,0) -> #N/A | J3: N/A | K3: =_xlfn.XLOOKUP(B3,Payroll!D:D,Payroll!F:F,,0) -> yes | L3: =_xlfn.XLOOKUP(B3,Payroll!D:D,Payroll!H:H,,0) -> 45759 | M3: =IF(L3>F3,"After","Before") -> After
A4: EMP0009 | B4: Ethan Baker | C4: Information Technology | D4: IT Operations Manager | E4: 44858 | F4: 44995 | G4: Terminated | H4: =_xlfn.XLOOKUP(B4,Finance!C:C,Finance!E:E,,0) -> Active | I4: =_xlfn.XLOOKUP(B4,Finance!C:C,Finance!G:G,,0) -> 45049 | J4: =IF(I4>F4,"After","Before") -> After | K4: =_xlfn.XLOOKUP(B4,Payroll!D:D,Payroll!F:F,,0) -> yes | L4: =_xlfn.XLOOKUP(B4,Payroll!D:D,Payroll!H:H,,0) -> 45025 | M4: =IF(L4>F4,"After","Before") -> After
A5: EMP0017 | B5: Leo Young | C5: Information Technology | D5: Cloud Engineer | E5: 42387 | F5: 43048 | G5: Terminated | H5: =_xlfn.XLOOKUP(B5,Finance!C:C,Finance!E:E,,0) -> Active | I5: =_xlfn.XLOOKUP(B5,Finance!C:C,Finance!G:G,,0) -> 43063 | J5: =IF(I5>F5,"After","Before") -> After | K5: =_xlfn.XLOOKUP(B5,Payroll!D:D,Payroll!F:F,,0) -> yes | L5: =_xlfn.XLOOKUP(B5,Payroll!D:D,Payroll!H:H,,0) -> 43091 | M5: =IF(L5>F5,"After","Before") -> After
A6: EMP0026 | B6: Ruby Thomas | C6: Information Technology | D6: Systems Administrator | E6: 45434 | F6: 45823 | G6: Terminated | H6: =_xlfn.XLOOKUP(B6,Finance!C:C,Finance!E:E,,0) -> Disabled | I6: =_xlfn.XLOOKUP(B6,Finance!C:C,Finance!G:G,,0) -> 45774 | J6: =IF(I6>F6,"After","Before") -> Before | K6: =_xlfn.XLOOKUP(B6,Payroll!D:D,Payroll!F:F,,0) -> no | L6: =_xlfn.XLOOKUP(B6,Payroll!D:D,Payroll!H:H,,0) -> 45804 | M6: N/A
A7: EMP0027 | B7: Layla Cook | C7: Human Resources | D7: HR Manager | E7: 43896 | F7: 46154 | G7: Terminated | H7: =_xlfn.XLOOKUP(B7,Finance!C:C,Finance!E:E,,0) -> #N/A | I7: =_xlfn.XLOOKUP(B7,Finance!C:C,Finance!G:G,,0) -> #N/A | J7: N/A | K7: =_xlfn.XLOOKUP(B7,Payroll!D:D,Payroll!F:F,,0) -> no | L7: =_xlfn.XLOOKUP(B7,Payroll!D:D,Payroll!H:H,,0) -> 46142 | M7: N/A
A8: EMP0040 | B8: Emily Collins | C8: Human Resources | D8: People Operations Analyst | E8: 42639 | F8: 44098 | G8: Terminated | H8: =_xlfn.XLOOKUP(B8,Finance!C:C,Finance!E:E,,0) -> Active | I8: =_xlfn.XLOOKUP(B8,Finance!C:C,Finance!G:G,,0) -> 44046 | J8: =IF(I8>F8,"After","Before") -> Before | K8: =_xlfn.XLOOKUP(B8,Payroll!D:D,Payroll!F:F,,0) -> no | L8: =_xlfn.XLOOKUP(B8,Payroll!D:D,Payroll!H:H,,0) -> 44091 | M8: N/A
A9: EMP0045 | B9: Nadia Murphy | C9: Engineering | D9: Data Engineer | E9: 45839 | F9: 46232 | G9: Terminated | H9: =_xlfn.XLOOKUP(B9,Finance!C:C,Finance!E:E,,0) -> #N/A | I9: =_xlfn.XLOOKUP(B9,Finance!C:C,Finance!G:G,,0) -> #N/A | J9: N/A | K9: =_xlfn.XLOOKUP(B9,Payroll!D:D,Payroll!F:F,,0) -> no | L9: =_xlfn.XLOOKUP(B9,Payroll!D:D,Payroll!H:H,,0) -> 46228 | M9: N/A
A10: EMP0052 | B10: Noah Bailey | C10: Operations | D10: Service Delivery Manager | E10: 44969 | F10: 45294 | G10: Terminated | H10: =_xlfn.XLOOKUP(B10,Finance!C:C,Finance!E:E,,0) -> Disabled | I10: =_xlfn.XLOOKUP(B10,Finance!C:C,Finance!G:G,,0) -> 45265 | J10: N/A | K10: =_xlfn.XLOOKUP(B10,Payroll!D:D,Payroll!F:F,,0) -> no | L10: =_xlfn.XLOOKUP(B10,Payroll!D:D,Payroll!H:H,,0) -> 45264 | M10: N/A
A11: EMP0053 | B11: Maya Stewart | C11: Legal & Compliance | D11: Legal Operations Specialist | E11: 42547 | F11: 43632 | G11: Terminated | H11: =_xlfn.XLOOKUP(B11,Finance!C:C,Finance!E:E,,0) -> Active | I11: =_xlfn.XLOOKUP(B11,Finance!C:C,Finance!G:G,,0) -> 43620 | J11: =IF(I11>F11,"After","Before") -> Before | K11: =_xlfn.XLOOKUP(B11,Payroll!D:D,Payroll!F:F,,0) -> no | L11: =_xlfn.XLOOKUP(B11,Payroll!D:D,Payroll!H:H,,0) -> 43625 | M11: N/A
A12: EMP0055 | B12: Benjamin Rogers | C12: Engineering | D12: Software Engineer | E12: 42844 | F12: 44088 | G12: Terminated | H12: =_xlfn.XLOOKUP(B12,Finance!C:C,Finance!E:E,,0) -> #N/A | I12: =_xlfn.XLOOKUP(B12,Finance!C:C,Finance!G:G,,0) -> #N/A | J12: N/A | K12: =_xlfn.XLOOKUP(B12,Payroll!D:D,Payroll!F:F,,0) -> no | L12: =_xlfn.XLOOKUP(B12,Payroll!D:D,Payroll!H:H,,0) -> 44069 | M12: N/A
A13: EMP0056 | B13: Maya Turner | C13: Sales | D13: Sales Development Representative | E13: 43038 | F13: 46223 | G13: Terminated | H13: =_xlfn.XLOOKUP(B13,Finance!C:C,Finance!E:E,,0) -> Disabled | I13: =_xlfn.XLOOKUP(B13,Finance!C:C,Finance!G:G,,0) -> 46209 | J13: =IF(I13>F13,"After","Before") -> Before | K13: =_xlfn.XLOOKUP(B13,Payroll!D:D,Payroll!F:F,,0) -> no | L13: =_xlfn.XLOOKUP(B13,Payroll!D:D,Payroll!H:H,,0) -> 46216 | M13: N/A
A14: EMP0058 | B14: James Evans | C14: Finance | D14: FP&A Analyst | E14: 45594 | F14: 45776 | G14: Terminated | H14: =_xlfn.XLOOKUP(B14,Finance!C:C,Finance!E:E,,0) -> Disabled | I14: =_xlfn.XLOOKUP(B14,Finance!C:C,Finance!G:G,,0) -> 45760 | J14: =IF(I14>F14,"After","Before") -> Before | K14: =_xlfn.XLOOKUP(B14,Payroll!D:D,Payroll!F:F,,0) -> no | L14: =_xlfn.XLOOKUP(B14,Payroll!D:D,Payroll!H:H,,0) -> 45769 | M14: N/A
A15: EMP0068 | B15: Hannah Brown | C15: Customer Support | D15: Service Desk Analyst | E15: 44491 | F15: 45453 | G15: Terminated | H15: =_xlfn.XLOOKUP(B15,Finance!C:C,Finance!E:E,,0) -> #N/A | I15: =_xlfn.XLOOKUP(B15,Finance!C:C,Finance!G:G,,0) -> #N/A | J15: N/A | K15: =_xlfn.XLOOKUP(B15,Payroll!D:D,Payroll!F:F,,0) -> no | L15: =_xlfn.XLOOKUP(B15,Payroll!D:D,Payroll!H:H,,0) -> 45443 | M15: N/A
A16: EMP0069 | B16: Nathan Brown | C16: Finance | D16: Financial Controller | E16: 45851 | F16: 46057 | G16: Terminated | H16: =_xlfn.XLOOKUP(B16,Finance!C:C,Finance!E:E,,0) -> Disabled | I16: =_xlfn.XLOOKUP(B16,Finance!C:C,Finance!G:G,,0) -> 45994 | J16: =IF(I16>F16,"After","Before") -> Before | K16: =_xlfn.XLOOKUP(B16,Payroll!D:D,Payroll!F:F,,0) -> no | L16: =_xlfn.XLOOKUP(B16,Payroll!D:D,Payroll!H:H,,0) -> 46036 | M16: N/A
A17: EMP0078 | B17: Sofia Reed | C17: Marketing | D17: Content Strategist | E17: 44358 | F17: 45140 | G17: Terminated | H17: =_xlfn.XLOOKUP(B17,Finance!C:C,Finance!E:E,,0) -> #N/A | I17: =_xlfn.XLOOKUP(B17,Finance!C:C,Finance!G:G,,0) -> #N/A | J17: N/A | K17: =_xlfn.XLOOKUP(B17,Payroll!D:D,Payroll!F:F,,0) -> no | L17: =_xlfn.XLOOKUP(B17,Payroll!D:D,Payroll!H:H,,0) -> 45136 | M17: N/A
A18: EMP0079 | B18: Chloe Phillips | C18: Finance | D18: Financial Controller | E18: 42804 | F18: 45077 | G18: Terminated | H18: =_xlfn.XLOOKUP(B18,Finance!C:C,Finance!E:E,,0) -> Disabled | I18: =_xlfn.XLOOKUP(B18,Finance!C:C,Finance!G:G,,0) -> 45076 | J18: =IF(I18>F18,"After","Before") -> Before | K18: =_xlfn.XLOOKUP(B18,Payroll!D:D,Payroll!F:F,,0) -> no | L18: =_xlfn.XLOOKUP(B18,Payroll!D:D,Payroll!H:H,,0) -> 45074 | M18: N/A
A19: EMP0081 | B19: Ruby Taylor | C19: Information Technology | D19: Network Engineer | E19: 44652 | F19: 45457 | G19: Terminated | H19: =_xlfn.XLOOKUP(B19,Finance!C:C,Finance!E:E,,0) -> Disabled | I19: =_xlfn.XLOOKUP(B19,Finance!C:C,Finance!G:G,,0) -> 45440 | J19: =IF(I19>F19,"After","Before") -> Before | K19: =_xlfn.XLOOKUP(B19,Payroll!D:D,Payroll!F:F,,0) -> no | L19: =_xlfn.XLOOKUP(B19,Payroll!D:D,Payroll!H:H,,0) -> 45443 | M19: N/A
A20: EMP0083 | B20: Leah Carter | C20: Marketing | D20: Marketing Manager | E20: 45323 | F20: 45964 | G20: Terminated | H20: =_xlfn.XLOOKUP(B20,Finance!C:C,Finance!E:E,,0) -> #N/A | I20: =_xlfn.XLOOKUP(B20,Finance!C:C,Finance!G:G,,0) -> #N/A | J20: N/A | K20: =_xlfn.XLOOKUP(B20,Payroll!D:D,Payroll!F:F,,0) -> no | L20: =_xlfn.XLOOKUP(B20,Payroll!D:D,Payroll!H:H,,0) -> 45955 | M20: N/A
A21: EMP0084 | B21: Layla Thomas | C21: Information Technology | D21: Infrastructure Engineer | E21: 42837 | F21: 43670 | G21: Terminated | H21: =_xlfn.XLOOKUP(B21,Finance!C:C,Finance!E:E,,0) -> Active | I21: =_xlfn.XLOOKUP(B21,Finance!C:C,Finance!G:G,,0) -> 43679 | J21: =IF(I21>F21,"After","Before") -> After | K21: =_xlfn.XLOOKUP(B21,Payroll!D:D,Payroll!F:F,,0) -> no | L21: =_xlfn.XLOOKUP(B21,Payroll!D:D,Payroll!H:H,,0) -> 43646 | M21: N/A
A22: EMP0089 | B22: Emily King | C22: Customer Support | D22: Service Desk Analyst | E22: 43058 | F22: 45257 | G22: Terminated | H22: =_xlfn.XLOOKUP(B22,Finance!C:C,Finance!E:E,,0) -> #N/A | I22: =_xlfn.XLOOKUP(B22,Finance!C:C,Finance!G:G,,0) -> #N/A | J22: N/A | K22: =_xlfn.XLOOKUP(B22,Payroll!D:D,Payroll!F:F,,0) -> no | L22: =_xlfn.XLOOKUP(B22,Payroll!D:D,Payroll!H:H,,0) -> 45244 | M22: N/A
A23: EMP0092 | B23: Daniel Parker | C23: Operations | D23: Operations Analyst | E23: 43186 | F23: 44244 | G23: Terminated | H23: =_xlfn.XLOOKUP(B23,Finance!C:C,Finance!E:E,,0) -> Disabled | I23: =_xlfn.XLOOKUP(B23,Finance!C:C,Finance!G:G,,0) -> 44227 | J23: =IF(I23>F23,"After","Before") -> Before | K23: =_xlfn.XLOOKUP(B23,Payroll!D:D,Payroll!F:F,,0) -> no | L23: =_xlfn.XLOOKUP(B23,Payroll!D:D,Payroll!H:H,,0) -> 44234 | M23: N/A
A24: EMP0095 | B24: Ethan Hall | C24: Information Security | D24: IAM Engineer | E24: 44504 | F24: 45854 | G24: Terminated | H24: =_xlfn.XLOOKUP(B24,Finance!C:C,Finance!E:E,,0) -> Disabled | I24: =_xlfn.XLOOKUP(B24,Finance!C:C,Finance!G:G,,0) -> 45840 | J24: =IF(I24>F24,"After","Before") -> Before | K24: =_xlfn.XLOOKUP(B24,Payroll!D:D,Payroll!F:F,,0) -> no | L24: =_xlfn.XLOOKUP(B24,Payroll!D:D,Payroll!H:H,,0) -> 45833 | M24: N/A

Sheet Employees
A1: employee_id | B1: employee_name | C1: department | D1: job_title | E1: start_date | F1: terminated_date | G1: status
A2: EMP0001 | B2: Amelia Bailey | C2: Finance | D2: Accountant | E2: 45703 | G2: Active
A3: EMP0002 | B3: Adam Carter | C3: Operations | D3: Service Delivery Manager | E3: 42578 | G3: Active
A4: EMP0003 | B4: Henry Murphy | C4: Human Resources | D4: HR Business Partner | E4: 45208 | F4: 45967 | G4: Terminated
A5: EMP0004 | B5: Jack Phillips | C5: Information Security | D5: Security Operations Manager | E5: 43425 | G5: Active
A6: EMP0005 | B6: Noah Wright | C6: Marketing | D6: Marketing Manager | E6: 43242 | G6: Active
A7: EMP0006 | B7: Henry Bailey | C7: Customer Support | D7: Service Desk Analyst | E7: 44765 | F7: 45719 | G7: Terminated
A8: EMP0007 | B8: Omar Edwards | C8: Engineering | D8: QA Engineer | E8: 42558 | G8: Active
A9: EMP0008 | B9: Benjamin Khan | C9: Sales | D9: Sales Development Representative | E9: 44171 | G9: Active
A10: EMP0009 | B10: Ethan Baker | C10: Information Technology | D10: IT Operations Manager | E10: 44858 | F10: 44995 | G10: Terminated
A11: EMP0010 | B11: Alice Evans | C11: Sales | D11: Sales Operations Analyst | E11: 45881 | G11: Active
A12: EMP0011 | B12: Ethan Stewart | C12: Operations | D12: Operations Analyst | E12: 45465 | G12: Active
A13: EMP0012 | B13: Nadia Morgan | C13: Customer Support | D13: Customer Support Specialist | E13: 45327 | G13: Active
A14: EMP0013 | B14: Oliver Cook | C14: Finance | D14: Finance Analyst | E14: 45056 | G14: Active
A15: EMP0014 | B15: Oliver Turner | C15: Engineering | D15: Engineering Manager | E15: 45685 | G15: Active
A16: EMP0015 | B16: Leah Wilson | C16: Human Resources | D16: HR Coordinator | E16: 42717 | G16: Active
A17: EMP0016 | B17: Hannah Campbell | C17: Information Security | D17: IAM Engineer | E17: 45173 | G17: Active
A18: EMP0017 | B18: Leo Young | C18: Information Technology | D18: Cloud Engineer | E18: 42387 | F18: 43048 | G18: Terminated
A19: EMP0018 | B19: Benjamin Walker | C19: Human Resources | D19: HR Coordinator | E19: 42790 | G19: Active
A20: EMP0019 | B20: Ella Morgan | C20: Operations | D20: Business Operations Specialist | E20: 44576 | G20: Active
A21: EMP0020 | B21: Sara Thomas | C21: Engineering | D21: Engineering Manager | E21: 42377 | G21: Active
A22: EMP0021 | B22: Yusuf Stewart | C22: Marketing | D22: Marketing Manager | E22: 46073 | G22: Active
A23: EMP0022 | B23: Yusuf Bailey | C23: Operations | D23: Operations Analyst | E23: 45208 | G23: Active
A24: EMP0023 | B24: Henry Murphy 2 | C24: Finance | D24: Accountant | E24: 44861 | G24: Active
A25: EMP0024 | B25: Chloe Murphy | C25: Engineering | D25: DevOps Engineer | E25: 44135 | G25: Active
A26: EMP0025 | B26: Chloe Smith | C26: Marketing | D26: Content Strategist | E26: 44960 | G26: Active
A27: EMP0026 | B27: Ruby Thomas | C27: Information Technology | D27: Systems Administrator | E27: 45434 | F27: 45823 | G27: Terminated
A28: EMP0027 | B28: Layla Cook | C28: Human Resources | D28: HR Manager | E28: 43896 | F28: 46154 | G28: Terminated
A29: EMP0028 | B29: Ethan King | C29: Finance | D29: Financial Controller | E29: 45396 | G29: Active
A30: EMP0029 | B30: Alice Carter | C30: Marketing | D30: Marketing Coordinator | E30: 45788 | G30: Active
A31: EMP0030 | B31: Isla Parker | C31: Operations | D31: Business Operations Specialist | E31: 43876 | G31: Active
A32: EMP0031 | B32: Leah Murphy | C32: Human Resources | D32: HR Manager | E32: 44827 | G32: Active
A33: EMP0032 | B33: Omar Thomas | C33: Information Technology | D33: Infrastructure Engineer | E33: 45669 | G33: Active
A34: EMP0033 | B34: Samuel Wright | C34: Engineering | D34: QA Engineer | E34: 44412 | G34: Active
A35: EMP0034 | B35: Sofia Carter | C35: Engineering | D35: DevOps Engineer | E35: 46141 | G35: Active
A36: EMP0035 | B36: Fatima Parker | C36: Information Technology | D36: Cloud Engineer | E36: 42938 | G36: Active
A37: EMP0036 | B37: Oliver Parker | C37: Sales | D37: Regional Sales Manager | E37: 43564 | G37: Active
A38: EMP0037 | B38: Oscar Campbell | C38: Sales | D38: Key Account Manager | E38: 45889 | G38: Active
A39: EMP0038 | B39: Daniel Bailey | C39: Customer Support | D39: Support Team Lead | E39: 43448 | G39: Active
A40: EMP0039 | B40: Priya Murphy | C40: Operations | D40: Operations Manager | E40: 43470 | G40: Active
...

Sheet Finance
A1: user_id | B1: user_name | C1: employee_name | D1: creation_date | E1: status | F1: access_group | G1: last_login_date
A2: FCU0001 | B2: amelia.bailey | C2: Amelia Bailey | D2: 45832 | E2: Active | F2: financecore_readonly | G2: 46148
A3: FCU0002 | B3: adam.carter | C3: Adam Carter | D3: 42673 | E3: Active | F3: financecore_readonly | G3: 46167
A4: FCU0003 | B4: jack.phillips | C4: Jack Phillips | D4: 43417 | E4: Active | F4: financecore_readonly | G4: 46222
A5: FCU0004 | B5: noah.wright | C5: Noah Wright | D5: 43741 | E5: Active | F5: financecore_readonly | G5: 46152
A6: FCU0005 | B6: ethan.baker | C6: Ethan Baker | D6: 44873 | E6: Active | F6: financecore_readonly | G6: 45049
A7: FCU0006 | B7: alice.evans | C7: Alice Evans | D7: 45968 | E7: Active | F7: financecore_readonly | G7: 46164
A8: FCU0007 | B8: ethan.stewart | C8: Ethan Stewart | D8: 45862 | E8: Active | F8: financecore_reporting | G8: 46270
A9: FCU0008 | B9: oliver.cook | C9: Oliver Cook | D9: 45071 | E9: Active | F9: financecore_readonly | G9: 46174
A10: FCU0009 | B10: oliver.turner | C10: Oliver Turner | D10: 46089 | E10: Active | F10: financecore_reporting | G10: 46273
A11: FCU0010 | B11: hannah.campbell | C11: Hannah Campbell | D11: 45176 | E11: Active | F11: financecore_support | G11: 46167
A12: FCU0011 | B12: leo.young | C12: Leo Young | D12: 43025 | E12: Active | F12: administrators | G12: 43063
A13: FCU0012 | B13: ella.morgan | C13: Ella Morgan | D13: 44663 | E13: Active | F13: financecore_readonly | G13: 46236
... A63: FCU0062 | B63: leo.young | C63: Leo Young 2 | D63: 43610 | E63: Active | F63: financecore_support | G63: 46204

Sheet Payroll
A1: employee_id | B1: user_id | C1: user_name | D1: employee_name | E1: creation_date | F1: is this active? | G1: access | H1: last sign in
A2: EMP0001 | B2: PAY0001 | C2: amelia.bailey0001 | D2: Amelia Bailey | E2: 45708 | F2: yes | G2: payroll_users | H2: 46256
A3: EMP0002 | B3: PAY0002 | C3: adam.carter0002 | D3: Adam Carter | E3: 42590 | F3: yes | G3: payroll_users | H3: 46263
A4: EMP0003 | B4: PAY0003 | C4: henry.murphy0003 | D4: Henry Murphy | E4: 45222 | F4: yes | G4: payroll_hr_admin | H4: 45994
A5: EMP0004 | B5: PAY0004 | C5: jack.phillips0004 | D5: Jack Phillips | E5: 43429 | F5: yes | G5: payroll_users | H5: 46248
A6: EMP0005 | B6: PAY0005 | C6: noah.wright0005 | D6: Noah Wright | E6: 43245 | F6: yes | G6: payroll_users | H6: 46277
A7: EMP0006 | B7: PAY0006 | C7: henry.bailey0006 | D7: Henry Bailey | E7: 44779 | F7: yes | G7: payroll_users | H7: 45759
A8: EMP0007 | B8: PAY0007 | C8: omar.edwards0007 | D8: Omar Edwards | E8: 42568 | F8: yes | G8: payroll_users | H8: 46204
A9: EMP0008 | B9: PAY0008 | C9: benjamin.khan0008 | D9: Benjamin Khan | E9: 44184 | F9: yes | G9: payroll_users | H9: 46248
A10: EMP0009 | B10: PAY0009 | C10: ethan.baker0009 | D10: Ethan Baker | E10: 44872 | F10: yes | G10: payroll_users | H10: 45025
A11: EMP0010 | B11: PAY0010 | C11: alice.evans0010 | D11: Alice Evans | E11: 45893 | F11: yes | G11: payroll_users | H11: 46240
A12: EMP0011 | B12: PAY0011 | C12: ethan.stewart0011 | D12: Ethan Stewart | E12: 45470 | F12: yes | G12: payroll_users | H12: 46271
A13: EMP0012 | B13: PAY0012 | C13: nadia.morgan0012 | D13: Nadia Morgan | E13: 45332 | F13: yes | G13: payroll_users | H13: 46228
... A101: EMP0100 | B101: PAY0100 | C101: leo.young0100 | D101: Leo Young 2 | E101: 43471 | F101: yes | G101: payroll_users | H101: 46273
